<?xml version="1.0"?>
<robot xmlns:xacro="http://www.ros.org/wiki/xacro" name="rudimentary_bot">

  <!-- Base Link (Chassis) -->
  <!-- base_link origin is raised so wheels are below/within chassis -->
  <link name="base_link">
    <visual>
      <origin xyz="0 0 0.15" rpy="0 0 0"/>
      <geometry>
        <box size="0.5 0.3 0.15"/>
      </geometry>
      <material name="blue">
        <color rgba="0 0 1 1"/>
      </material>
    </visual>
    <collision>
      <origin xyz="0 0 0.15" rpy="0 0 0"/>
      <geometry>
        <box size="0.5 0.3 0.15"/>
      </geometry>
    </collision>
    <inertial>
      <origin xyz="0 0 0.15" rpy="0 0 0"/>
      <mass value="10.0"/>
      <inertia ixx="0.1" ixy="0" ixz="0" iyy="0.1" iyz="0" izz="0.1"/>
    </inertial>
  </link>

  <!-- Left Wheel -->
  <link name="left_wheel">
    <visual>
      <origin xyz="0 0 0" rpy="1.5708 0 0"/>
      <geometry>
        <cylinder radius="0.1" length="0.05"/>
      </geometry>
      <material name="light_gray">
        <color rgba="0.7 0.7 0.7 1"/>
      </material>
    </visual>
    <collision>
      <origin xyz="0 0 0" rpy="1.5708 0 0"/>
      <geometry>
        <cylinder radius="0.1" length="0.05"/>
      </geometry>
    </collision>
    <inertial>
      <mass value="1.0"/>
      <inertia ixx="0.005" ixy="0" ixz="0" iyy="0.005" iyz="0" izz="0.01"/>
    </inertial>
  </link>

  <!-- Right Wheel -->
  <link name="right_wheel">
    <visual>
      <origin xyz="0 0 0" rpy="1.5708 0 0"/>
      <geometry>
        <cylinder radius="0.1" length="0.05"/>
      </geometry>
      <material name="light_gray">
        <color rgba="0.7 0.7 0.7 1"/>
      </material>
    </visual>
    <collision>
      <origin xyz="0 0 0" rpy="1.5708 0 0"/>
      <geometry>
        <cylinder radius="0.1" length="0.05"/>
      </geometry>
    </collision>
    <inertial>
      <mass value="1.0"/>
      <inertia ixx="0.005" ixy="0" ixz="0" iyy="0.005" iyz="0" izz="0.01"/>
    </inertial>
  </link>

  <!-- Rear Caster Wheel -->
  <link name="caster_wheel">
    <visual>
      <origin xyz="0 0 0" rpy="0 0 0"/>
      <geometry>
        <sphere radius="0.05"/>
      </geometry>
      <material name="gray">
        <color rgba="0.5 0.5 0.5 1"/>
      </material>
    </visual>
    <collision>
      <origin xyz="0 0 0" rpy="0 0 0"/>
      <geometry>
        <sphere radius="0.05"/>
      </geometry>
    </collision>
    <inertial>
      <mass value="0.5"/>
      <inertia ixx="0.001" ixy="0" ixz="0" iyy="0.001" iyz="0" izz="0.001"/>
    </inertial>
  </link>

  <!-- Front Caster Wheel (prevents forward pitch during braking) -->
  <link name="front_caster_wheel">
    <visual>
      <origin xyz="0 0 0" rpy="0 0 0"/>
      <geometry>
        <sphere radius="0.05"/>
      </geometry>
      <material name="gray">
        <color rgba="0.5 0.5 0.5 1"/>
      </material>
    </visual>
    <collision>
      <origin xyz="0 0 0" rpy="0 0 0"/>
      <geometry>
        <sphere radius="0.05"/>
      </geometry>
    </collision>
    <inertial>
      <mass value="0.5"/>
      <inertia ixx="0.001" ixy="0" ixz="0" iyy="0.001" iyz="0" izz="0.001"/>
    </inertial>
  </link>

  <!-- Laser Link (Forward-facing, X-axis) -->
  <link name="laser_link">
    <visual>
      <origin xyz="0 0 0" rpy="0 0 0"/>
      <geometry>
        <cylinder radius="0.05" length="0.1"/>
      </geometry>
      <material name="red">
        <color rgba="1 0 0 1"/>
      </material>
    </visual>
    <inertial>
      <mass value="0.1"/>
      <inertia ixx="0.001" ixy="0" ixz="0" iyy="0.001" iyz="0" izz="0.001"/>
    </inertial>
  </link>

  <!-- IMU Link -->
  <link name="imu_link">
    <inertial>
      <mass value="0.01"/>
      <inertia ixx="0.0001" ixy="0" ixz="0" iyy="0.0001" iyz="0" izz="0.0001"/>
    </inertial>
  </link>

  <!-- Joints -->
  <joint name="left_wheel_joint" type="continuous">
    <parent link="base_link"/>
    <child link="left_wheel"/>
    <origin xyz="0 0.175 0.1" rpy="0 0 0"/>
    <axis xyz="0 1 0"/>
  </joint>

  <joint name="right_wheel_joint" type="continuous">
    <parent link="base_link"/>
    <child link="right_wheel"/>
    <origin xyz="0 -0.175 0.1" rpy="0 0 0"/>
    <axis xyz="0 1 0"/>
  </joint>

  <joint name="caster_wheel_joint" type="fixed">
    <parent link="base_link"/>
    <child link="caster_wheel"/>
    <origin xyz="-0.2 0 0.05" rpy="0 0 0"/>
  </joint>

  <joint name="front_caster_wheel_joint" type="fixed">
    <parent link="base_link"/>
    <child link="front_caster_wheel"/>
    <!-- Front caster wheel positioned at front of chassis (x=0.25m is front edge of 0.5m chassis) -->
    <!-- Prevents forward pitch during braking, eliminating false wall detections from ground -->
    <origin xyz="0.25 0 0.05" rpy="0 0 0"/>
  </joint>

  <joint name="laser_joint" type="fixed">
    <parent link="base_link"/>
    <child link="laser_link"/>
    <!-- Centered (x=0, y=0) and raised to avoid chassis/wheel occlusion -->
    <!-- Chassis top is at z=0.225, wheels top at z=0.2 -->
    <!-- With front caster wheel preventing forward pitch, z=0.25m is sufficient (just above chassis) -->
    <origin xyz="0 0 0.25" rpy="0 0 0"/>
  </joint>

  <joint name="imu_joint" type="fixed">
    <parent link="base_link"/>
    <child link="imu_link"/>
    <origin xyz="0 0 0.15" rpy="0 0 0"/>
  </joint>

  <!-- Gazebo Plugins -->
  
  <!-- Differential Drive Plugin -->
  <gazebo>
    <plugin filename="gz-sim-diff-drive-system" name="gz::sim::systems::DiffDrive">
      <left_joint>left_wheel_joint</left_joint>
      <right_joint>right_wheel_joint</right_joint>
      <wheel_separation>0.35</wheel_separation>
      <wheel_radius>0.1</wheel_radius>
      <odom_publish_frequency>50</odom_publish_frequency>
      <topic>cmd_vel</topic>
      <odom_topic>odom</odom_topic>
      <publish_odom>true</publish_odom>
      <!-- CRITICAL: Set to false so EKF handles TF -->
      <publish_odom_tf>false</publish_odom_tf>
      <frame_id>odom</frame_id>
      <child_frame_id>base_link</child_frame_id>
      <max_linear_velocity>0.5</max_linear_velocity>
      <max_angular_velocity>1.0</max_angular_velocity>
    </plugin>
  </gazebo>

  <!-- Lidar Sensor Plugin -->
  <gazebo reference="laser_link">
    <sensor name="lidar" type="gpu_lidar">
      <pose>0 0 0 0 0 0</pose>
      <update_rate>10</update_rate>  <!-- Reduced to 10Hz to prevent RViz message queue overflow -->
      <topic>scan</topic>
      <gz_frame_id>laser_link</gz_frame_id>
      <always_on>true</always_on>
      <visualize>true</visualize>
      <!-- Try CPU lidar if gpu_lidar has rendering artifacts causing false walls -->
      <!-- No visibility mask - rely on height (z=0.5m) and min_range (0.4m) to avoid self-hits -->
      <lidar>
        <scan>
          <horizontal>
            <samples>360</samples>
            <resolution>1</resolution>
            <min_angle>-3.14159</min_angle>
            <max_angle>3.14159</max_angle>
          </horizontal>
          <vertical>
            <samples>1</samples>
            <resolution>0.01</resolution>
            <min_angle>0</min_angle>
            <max_angle>0</max_angle>
          </vertical>
        </scan>
        <range>
          <min>0.4</min>  <!-- Increased to 0.4m to completely eliminate robot body hits -->
          <!-- Chassis corners: sqrt(0.25^2 + 0.15^2) ≈ 0.29m. Wheels extend to ~0.275m from center. -->
          <!-- With LIDAR at z=0.5m, 0.4m min range ensures no false wall detections from robot body -->
          <max>10.0</max> <!-- Increased physical sensor range to see across rooms -->
          <resolution>0.01</resolution>
        </range>
      </lidar>
    </sensor>
  </gazebo>

  <!-- IMU Sensor Plugin -->
  <gazebo reference="imu_link">
    <sensor name="imu" type="imu">
      <pose>0 0 0 0 0 0</pose>
      <update_rate>100</update_rate>
      <topic>imu</topic>
      <gz_frame_id>imu_link</gz_frame_id>
      <imu>
        <angular_velocity>
          <x>
            <noise type="gaussian">
              <mean>0.0</mean>
              <stddev>0.0002</stddev>
            </noise>
          </x>
          <y>
            <noise type="gaussian">
              <mean>0.0</mean>
              <stddev>0.0002</stddev>
            </noise>
          </y>
          <z>
            <noise type="gaussian">
              <mean>0.0</mean>
              <stddev>0.0002</stddev>
            </noise>
          </z>
        </angular_velocity>
        <linear_acceleration>
          <x>
            <noise type="gaussian">
              <mean>0.0</mean>
              <stddev>0.017</stddev>
            </noise>
          </x>
          <y>
            <noise type="gaussian">
              <mean>0.0</mean>
              <stddev>0.017</stddev>
            </noise>
          </y>
          <z>
            <noise type="gaussian">
              <mean>0.0</mean>
              <stddev>0.017</stddev>
            </noise>
          </z>
        </linear_acceleration>
      </imu>
    </sensor>
  </gazebo>

</robot>
